2018-09-10 13:31:38,951 INFO app root
2018-09-10 13:31:38,954 INFO executed activate virtualenv
2018-09-10 13:31:38,954 INFO executed path insert
2018-09-10 13:31:38,956 INFO beacon decode as a test
2018-09-10 13:31:39,483 INFO numpy pandas and itertools
2018-09-10 13:31:39,604 INFO imported matplotlib
2018-09-10 13:31:39,611 INFO imported math, sys, os and xlrd
2018-09-10 13:31:39,611 INFO datetime and csv
2018-09-10 13:31:39,630 INFO collections and simplekml
2018-09-10 13:31:39,630 INFO re and beacon decode
2018-09-10 13:31:39,630 INFO pypyodbc imported - all modules imported
2018-09-10 13:31:39,775 INFO imported app
2018-09-10 13:31:39,775 INFO imported application as app
2018-09-10 13:31:52,875 DEBUG Starting new HTTP connection (1): jrreich.myftp.org
2018-09-10 13:31:52,934 ERROR Exception on /api/MEO/location_accuracy/3385 [GET]
Traceback (most recent call last):
  File "C:\Users\jrrei\Source\Repos\MEO_Analysis_HTML_Interface\env\Lib\site-packages\flask\app.py", line 1988, in wsgi_app
    response = self.full_dispatch_request()
  File "C:\Users\jrrei\Source\Repos\MEO_Analysis_HTML_Interface\env\Lib\site-packages\flask\app.py", line 1641, in full_dispatch_request
    rv = self.handle_user_exception(e)
  File "C:\Users\jrrei\Source\Repos\MEO_Analysis_HTML_Interface\env\Lib\site-packages\flask\app.py", line 1544, in handle_user_exception
    reraise(exc_type, exc_value, tb)
  File "C:\Users\jrrei\Source\Repos\MEO_Analysis_HTML_Interface\env\Lib\site-packages\flask\app.py", line 1639, in full_dispatch_request
    rv = self.dispatch_request()
  File "C:\Users\jrrei\Source\Repos\MEO_Analysis_HTML_Interface\env\Lib\site-packages\flask\app.py", line 1625, in dispatch_request
    return self.view_functions[rule.endpoint](**req.view_args)
  File "C:\Users\jrrei\Source\Repos\MEO_Analysis_HTML_Interface\routes.py", line 379, in meolut_location_accuracy
    EndTime = datetime.datetime.strptime(request.args.get('EndTime'), '%Y-%m-%d %H:%M:%S')
  File "C:\Users\jrrei\Anaconda2\Lib\_strptime.py", line 335, in _strptime
    data_string[found.end():])
ValueError: unconverted data remains: .610000
2018-09-10 13:31:52,938 DEBUG http://jrreich.myftp.org:80 "GET /api/MEO/location_accuracy/3385?EndTime=2018-09-10+17%3A31%3A51.610000&StartTime=2018-09-10+13%3A31%3A51.610000 HTTP/1.1" 500 291
2018-09-10 13:31:52,938 ERROR Exception on /RealTimeMonitor [GET]
Traceback (most recent call last):
  File "C:\Users\jrrei\Source\Repos\MEO_Analysis_HTML_Interface\env\Lib\site-packages\flask\app.py", line 1988, in wsgi_app
    response = self.full_dispatch_request()
  File "C:\Users\jrrei\Source\Repos\MEO_Analysis_HTML_Interface\env\Lib\site-packages\flask\app.py", line 1641, in full_dispatch_request
    rv = self.handle_user_exception(e)
  File "C:\Users\jrrei\Source\Repos\MEO_Analysis_HTML_Interface\env\Lib\site-packages\flask\app.py", line 1544, in handle_user_exception
    reraise(exc_type, exc_value, tb)
  File "C:\Users\jrrei\Source\Repos\MEO_Analysis_HTML_Interface\env\Lib\site-packages\flask\app.py", line 1639, in full_dispatch_request
    rv = self.dispatch_request()
  File "C:\Users\jrrei\Source\Repos\MEO_Analysis_HTML_Interface\env\Lib\site-packages\flask\app.py", line 1625, in dispatch_request
    return self.view_functions[rule.endpoint](**req.view_args)
  File "C:\Users\jrrei\Source\Repos\MEO_Analysis_HTML_Interface\routes.py", line 185, in realtimemonitor
    StartTime = BurstStartTime, EndTime = EndTime),verify = False).content)
  File "C:\Users\jrrei\Anaconda2\Lib\json\__init__.py", line 339, in loads
    return _default_decoder.decode(s)
  File "C:\Users\jrrei\Anaconda2\Lib\json\decoder.py", line 364, in decode
    obj, end = self.raw_decode(s, idx=_w(s, 0).end())
  File "C:\Users\jrrei\Anaconda2\Lib\json\decoder.py", line 382, in raw_decode
    raise ValueError("No JSON object could be decoded")
ValueError: No JSON object could be decoded
2018-09-10 13:31:56,127 DEBUG Starting new HTTP connection (1): jrreich.myftp.org
2018-09-10 13:31:56,131 ERROR Exception on /api/MEO/location_accuracy/3385 [GET]
Traceback (most recent call last):
  File "C:\Users\jrrei\Source\Repos\MEO_Analysis_HTML_Interface\env\Lib\site-packages\flask\app.py", line 1988, in wsgi_app
    response = self.full_dispatch_request()
  File "C:\Users\jrrei\Source\Repos\MEO_Analysis_HTML_Interface\env\Lib\site-packages\flask\app.py", line 1641, in full_dispatch_request
    rv = self.handle_user_exception(e)
  File "C:\Users\jrrei\Source\Repos\MEO_Analysis_HTML_Interface\env\Lib\site-packages\flask\app.py", line 1544, in handle_user_exception
    reraise(exc_type, exc_value, tb)
  File "C:\Users\jrrei\Source\Repos\MEO_Analysis_HTML_Interface\env\Lib\site-packages\flask\app.py", line 1639, in full_dispatch_request
    rv = self.dispatch_request()
  File "C:\Users\jrrei\Source\Repos\MEO_Analysis_HTML_Interface\env\Lib\site-packages\flask\app.py", line 1625, in dispatch_request
    return self.view_functions[rule.endpoint](**req.view_args)
  File "C:\Users\jrrei\Source\Repos\MEO_Analysis_HTML_Interface\routes.py", line 379, in meolut_location_accuracy
    EndTime = datetime.datetime.strptime(request.args.get('EndTime'), '%Y-%m-%d %H:%M:%S')
  File "C:\Users\jrrei\Anaconda2\Lib\_strptime.py", line 335, in _strptime
    data_string[found.end():])
ValueError: unconverted data remains: .979000
2018-09-10 13:31:56,132 DEBUG http://jrreich.myftp.org:80 "GET /api/MEO/location_accuracy/3385?EndTime=2018-09-10+17%3A31%3A54.979000&StartTime=2018-09-10+13%3A31%3A54.979000 HTTP/1.1" 500 291
2018-09-10 13:31:56,132 ERROR Exception on /RealTimeMonitor [GET]
Traceback (most recent call last):
  File "C:\Users\jrrei\Source\Repos\MEO_Analysis_HTML_Interface\env\Lib\site-packages\flask\app.py", line 1988, in wsgi_app
    response = self.full_dispatch_request()
  File "C:\Users\jrrei\Source\Repos\MEO_Analysis_HTML_Interface\env\Lib\site-packages\flask\app.py", line 1641, in full_dispatch_request
    rv = self.handle_user_exception(e)
  File "C:\Users\jrrei\Source\Repos\MEO_Analysis_HTML_Interface\env\Lib\site-packages\flask\app.py", line 1544, in handle_user_exception
    reraise(exc_type, exc_value, tb)
  File "C:\Users\jrrei\Source\Repos\MEO_Analysis_HTML_Interface\env\Lib\site-packages\flask\app.py", line 1639, in full_dispatch_request
    rv = self.dispatch_request()
  File "C:\Users\jrrei\Source\Repos\MEO_Analysis_HTML_Interface\env\Lib\site-packages\flask\app.py", line 1625, in dispatch_request
    return self.view_functions[rule.endpoint](**req.view_args)
  File "C:\Users\jrrei\Source\Repos\MEO_Analysis_HTML_Interface\routes.py", line 185, in realtimemonitor
    StartTime = BurstStartTime, EndTime = EndTime),verify = False).content)
  File "C:\Users\jrrei\Anaconda2\Lib\json\__init__.py", line 339, in loads
    return _default_decoder.decode(s)
  File "C:\Users\jrrei\Anaconda2\Lib\json\decoder.py", line 364, in decode
    obj, end = self.raw_decode(s, idx=_w(s, 0).end())
  File "C:\Users\jrrei\Anaconda2\Lib\json\decoder.py", line 382, in raw_decode
    raise ValueError("No JSON object could be decoded")
ValueError: No JSON object could be decoded
2018-09-10 13:32:02,256 DEBUG Starting new HTTP connection (1): jrreich.myftp.org
2018-09-10 13:32:02,259 ERROR Exception on /api/MEO/location_accuracy/3385 [GET]
Traceback (most recent call last):
  File "C:\Users\jrrei\Source\Repos\MEO_Analysis_HTML_Interface\env\Lib\site-packages\flask\app.py", line 1988, in wsgi_app
    response = self.full_dispatch_request()
  File "C:\Users\jrrei\Source\Repos\MEO_Analysis_HTML_Interface\env\Lib\site-packages\flask\app.py", line 1641, in full_dispatch_request
    rv = self.handle_user_exception(e)
  File "C:\Users\jrrei\Source\Repos\MEO_Analysis_HTML_Interface\env\Lib\site-packages\flask\app.py", line 1544, in handle_user_exception
    reraise(exc_type, exc_value, tb)
  File "C:\Users\jrrei\Source\Repos\MEO_Analysis_HTML_Interface\env\Lib\site-packages\flask\app.py", line 1639, in full_dispatch_request
    rv = self.dispatch_request()
  File "C:\Users\jrrei\Source\Repos\MEO_Analysis_HTML_Interface\env\Lib\site-packages\flask\app.py", line 1625, in dispatch_request
    return self.view_functions[rule.endpoint](**req.view_args)
  File "C:\Users\jrrei\Source\Repos\MEO_Analysis_HTML_Interface\routes.py", line 379, in meolut_location_accuracy
    EndTime = datetime.datetime.strptime(request.args.get('EndTime'), '%Y-%m-%d %H:%M:%S')
  File "C:\Users\jrrei\Anaconda2\Lib\_strptime.py", line 335, in _strptime
    data_string[found.end():])
ValueError: unconverted data remains: .119000
2018-09-10 13:32:02,262 DEBUG http://jrreich.myftp.org:80 "GET /api/MEO/location_accuracy/3385?EndTime=2018-09-10+17%3A32%3A01.119000&StartTime=2018-09-10+16%3A32%3A01.119000 HTTP/1.1" 500 291
2018-09-10 13:32:02,263 ERROR Exception on /RealTimeMonitor [GET]
Traceback (most recent call last):
  File "C:\Users\jrrei\Source\Repos\MEO_Analysis_HTML_Interface\env\Lib\site-packages\flask\app.py", line 1988, in wsgi_app
    response = self.full_dispatch_request()
  File "C:\Users\jrrei\Source\Repos\MEO_Analysis_HTML_Interface\env\Lib\site-packages\flask\app.py", line 1641, in full_dispatch_request
    rv = self.handle_user_exception(e)
  File "C:\Users\jrrei\Source\Repos\MEO_Analysis_HTML_Interface\env\Lib\site-packages\flask\app.py", line 1544, in handle_user_exception
    reraise(exc_type, exc_value, tb)
  File "C:\Users\jrrei\Source\Repos\MEO_Analysis_HTML_Interface\env\Lib\site-packages\flask\app.py", line 1639, in full_dispatch_request
    rv = self.dispatch_request()
  File "C:\Users\jrrei\Source\Repos\MEO_Analysis_HTML_Interface\env\Lib\site-packages\flask\app.py", line 1625, in dispatch_request
    return self.view_functions[rule.endpoint](**req.view_args)
  File "C:\Users\jrrei\Source\Repos\MEO_Analysis_HTML_Interface\routes.py", line 185, in realtimemonitor
    StartTime = BurstStartTime, EndTime = EndTime),verify = False).content)
  File "C:\Users\jrrei\Anaconda2\Lib\json\__init__.py", line 339, in loads
    return _default_decoder.decode(s)
  File "C:\Users\jrrei\Anaconda2\Lib\json\decoder.py", line 364, in decode
    obj, end = self.raw_decode(s, idx=_w(s, 0).end())
  File "C:\Users\jrrei\Anaconda2\Lib\json\decoder.py", line 382, in raw_decode
    raise ValueError("No JSON object could be decoded")
ValueError: No JSON object could be decoded
2018-09-10 13:32:06,312 DEBUG Starting new HTTP connection (1): jrreich.myftp.org
2018-09-10 13:32:06,316 ERROR Exception on /api/MEO/location_accuracy/3385 [GET]
Traceback (most recent call last):
  File "C:\Users\jrrei\Source\Repos\MEO_Analysis_HTML_Interface\env\Lib\site-packages\flask\app.py", line 1988, in wsgi_app
    response = self.full_dispatch_request()
  File "C:\Users\jrrei\Source\Repos\MEO_Analysis_HTML_Interface\env\Lib\site-packages\flask\app.py", line 1641, in full_dispatch_request
    rv = self.handle_user_exception(e)
  File "C:\Users\jrrei\Source\Repos\MEO_Analysis_HTML_Interface\env\Lib\site-packages\flask\app.py", line 1544, in handle_user_exception
    reraise(exc_type, exc_value, tb)
  File "C:\Users\jrrei\Source\Repos\MEO_Analysis_HTML_Interface\env\Lib\site-packages\flask\app.py", line 1639, in full_dispatch_request
    rv = self.dispatch_request()
  File "C:\Users\jrrei\Source\Repos\MEO_Analysis_HTML_Interface\env\Lib\site-packages\flask\app.py", line 1625, in dispatch_request
    return self.view_functions[rule.endpoint](**req.view_args)
  File "C:\Users\jrrei\Source\Repos\MEO_Analysis_HTML_Interface\routes.py", line 379, in meolut_location_accuracy
    EndTime = datetime.datetime.strptime(request.args.get('EndTime'), '%Y-%m-%d %H:%M:%S')
  File "C:\Users\jrrei\Anaconda2\Lib\_strptime.py", line 335, in _strptime
    data_string[found.end():])
ValueError: unconverted data remains: .176000
2018-09-10 13:32:06,318 DEBUG http://jrreich.myftp.org:80 "GET /api/MEO/location_accuracy/3385?EndTime=2018-09-10+17%3A32%3A05.176000&StartTime=2018-09-10+16%3A32%3A05.176000 HTTP/1.1" 500 291
2018-09-10 13:32:06,319 ERROR Exception on /RealTimeMonitor [GET]
Traceback (most recent call last):
  File "C:\Users\jrrei\Source\Repos\MEO_Analysis_HTML_Interface\env\Lib\site-packages\flask\app.py", line 1988, in wsgi_app
    response = self.full_dispatch_request()
  File "C:\Users\jrrei\Source\Repos\MEO_Analysis_HTML_Interface\env\Lib\site-packages\flask\app.py", line 1641, in full_dispatch_request
    rv = self.handle_user_exception(e)
  File "C:\Users\jrrei\Source\Repos\MEO_Analysis_HTML_Interface\env\Lib\site-packages\flask\app.py", line 1544, in handle_user_exception
    reraise(exc_type, exc_value, tb)
  File "C:\Users\jrrei\Source\Repos\MEO_Analysis_HTML_Interface\env\Lib\site-packages\flask\app.py", line 1639, in full_dispatch_request
    rv = self.dispatch_request()
  File "C:\Users\jrrei\Source\Repos\MEO_Analysis_HTML_Interface\env\Lib\site-packages\flask\app.py", line 1625, in dispatch_request
    return self.view_functions[rule.endpoint](**req.view_args)
  File "C:\Users\jrrei\Source\Repos\MEO_Analysis_HTML_Interface\routes.py", line 185, in realtimemonitor
    StartTime = BurstStartTime, EndTime = EndTime),verify = False).content)
  File "C:\Users\jrrei\Anaconda2\Lib\json\__init__.py", line 339, in loads
    return _default_decoder.decode(s)
  File "C:\Users\jrrei\Anaconda2\Lib\json\decoder.py", line 364, in decode
    obj, end = self.raw_decode(s, idx=_w(s, 0).end())
  File "C:\Users\jrrei\Anaconda2\Lib\json\decoder.py", line 382, in raw_decode
    raise ValueError("No JSON object could be decoded")
ValueError: No JSON object could be decoded
2018-09-10 13:59:49,539 DEBUG Starting new HTTP connection (1): jrreich.myftp.org
2018-09-10 13:59:49,572 ERROR Exception on /api/MEO/location_accuracy/3385 [GET]
Traceback (most recent call last):
  File "C:\Users\jrrei\Source\Repos\MEO_Analysis_HTML_Interface\env\Lib\site-packages\flask\app.py", line 1988, in wsgi_app
    response = self.full_dispatch_request()
  File "C:\Users\jrrei\Source\Repos\MEO_Analysis_HTML_Interface\env\Lib\site-packages\flask\app.py", line 1641, in full_dispatch_request
    rv = self.handle_user_exception(e)
  File "C:\Users\jrrei\Source\Repos\MEO_Analysis_HTML_Interface\env\Lib\site-packages\flask\app.py", line 1544, in handle_user_exception
    reraise(exc_type, exc_value, tb)
  File "C:\Users\jrrei\Source\Repos\MEO_Analysis_HTML_Interface\env\Lib\site-packages\flask\app.py", line 1639, in full_dispatch_request
    rv = self.dispatch_request()
  File "C:\Users\jrrei\Source\Repos\MEO_Analysis_HTML_Interface\env\Lib\site-packages\flask\app.py", line 1625, in dispatch_request
    return self.view_functions[rule.endpoint](**req.view_args)
  File "C:\Users\jrrei\Source\Repos\MEO_Analysis_HTML_Interface\routes.py", line 379, in meolut_location_accuracy
    @app.route('/api/MEO/location_accuracy/<int:MEOLUT_ID>', methods=['GET'])
  File "C:\Users\jrrei\Anaconda2\Lib\_strptime.py", line 335, in _strptime
    data_string[found.end():])
ValueError: unconverted data remains: .396000
2018-09-10 13:59:49,575 DEBUG http://jrreich.myftp.org:80 "GET /api/MEO/location_accuracy/3385?EndTime=2018-09-10+17%3A59%3A48.396000&StartTime=2018-09-10+16%3A59%3A48.396000 HTTP/1.1" 500 291
2018-09-10 13:59:49,575 ERROR Exception on /RealTimeMonitor [GET]
Traceback (most recent call last):
  File "C:\Users\jrrei\Source\Repos\MEO_Analysis_HTML_Interface\env\Lib\site-packages\flask\app.py", line 1988, in wsgi_app
    response = self.full_dispatch_request()
  File "C:\Users\jrrei\Source\Repos\MEO_Analysis_HTML_Interface\env\Lib\site-packages\flask\app.py", line 1641, in full_dispatch_request
    rv = self.handle_user_exception(e)
  File "C:\Users\jrrei\Source\Repos\MEO_Analysis_HTML_Interface\env\Lib\site-packages\flask\app.py", line 1544, in handle_user_exception
    reraise(exc_type, exc_value, tb)
  File "C:\Users\jrrei\Source\Repos\MEO_Analysis_HTML_Interface\env\Lib\site-packages\flask\app.py", line 1639, in full_dispatch_request
    rv = self.dispatch_request()
  File "C:\Users\jrrei\Source\Repos\MEO_Analysis_HTML_Interface\env\Lib\site-packages\flask\app.py", line 1625, in dispatch_request
    return self.view_functions[rule.endpoint](**req.view_args)
  File "C:\Users\jrrei\Source\Repos\MEO_Analysis_HTML_Interface\routes.py", line 185, in realtimemonitor
    #HI_location_accuracy = MEOInput_Analysis.MEOLUT_percent(BurstStartTime, EndTime, servername,mcctestLGM)  #, sql_login = 'yes')
  File "C:\Users\jrrei\Anaconda2\Lib\json\__init__.py", line 339, in loads
    return _default_decoder.decode(s)
  File "C:\Users\jrrei\Anaconda2\Lib\json\decoder.py", line 364, in decode
    obj, end = self.raw_decode(s, idx=_w(s, 0).end())
  File "C:\Users\jrrei\Anaconda2\Lib\json\decoder.py", line 382, in raw_decode
    raise ValueError("No JSON object could be decoded")
ValueError: No JSON object could be decoded
